Workbook

Sheet Instructions
A1: মাল্টি-সেগমেন্ট একাউন্টিং ও ম্যানুফ্যাকচারিং ওয়ার্কবুক — ব্যবহার নির্দেশিকা
A3: কালার লেজেন্ড (Color Legend)
A4: নীল লেখা (Blue text) = আপনি নিজে টাইপ করবেন (Input)
A5: কালো লেখা (Black text) = ফর্মুলা — এখানে কিছু লিখবেন না, এটা Auto ক্যালকুলেট হয়
A6: হলুদ ফিল (Yellow fill) = গুরুত্বপূর্ণ Assumption / Cutover Date — ব্যবহারের আগে চেক করে নিন
A8: শীট অনুযায়ী কাজের ধারা (Sheet-by-Sheet Workflow)
A9: ১. Chart of Accounts (COA) — আপনার সব Account-এর তালিকা, প্রতিটা Account একটা Segment ট্যাগ করা (Import / Manufacturing / Packaging / Trading / Application / Shared)। নতুন Account লাগলে এখানেই প্রথমে যোগ করুন, বাকি সব শীট এখান থেকেই Account খুঁজে নেয়।
A10: ২. Opening Balances — Cutover Date (যেদিন থেকে এই নতুন সিস্টেমে সুইচ করবেন) পর্যন্ত আপনার Trial Balance। Total Debit = Total Credit মিলতেই হবে।
A11: ৩. Journal Entries — Cutover Date-এর পর থেকে প্রতিটা নতুন লেনদেন এখানে লিখবেন (এখন যেহেতু ওয়েবসাইট বাদ, এই শীটেই সরাসরি Manual এন্ট্রি দেবেন)। নিচে Total Debit ও Total Credit অবশ্যই সমান হতে হবে।
A12: ৪. Item Master — প্রতিটা স্টক আইটেম (কাঁচামাল, WIP, তৈরি পণ্য, প্যাকেজিং, ট্রেডিং, ইমপোর্ট করা পণ্য)। Current Qty ও Current Avg Cost সয়ংক্রিয়ভাবে Inventory Ledger থেকে হিসাব হয়।
A13: ৫. BOM Master — আপনার Multi-Stage BOM (Bill of Materials)। প্রতিটা সারিতে (Parent Item -> Component Item) সম্পর্ক থাকে। একটা Finished Good-এর Component নিজেই একটা WIP আইটেম হতে পারে, যার আবার নিজস্ব BOM আছে — এভাবেই Multi-Stage Manufacturing (Stage 1: কাঁচামাল -> Stage 2: আধা-তৈরি -> Stage 3: তৈরি পণ্য) রিপ্রেজেন্ট করা হয়েছে।
A14: ৬. Production Entry — প্রতিটা প্রোডাকশন রান এখানে রেকর্ড করুন। Item Produced ও Qty Produced দিন, প্রতিটা Component আলাদা সারিতে লিখুন। Qty per Unit ও Component Cost BOM Master ও Item Master থেকে Auto চলে আসবে। অর্ডারের এক সারিতে Labor & Overhead যোগ করুন। Total Production Cost ও Unit Cost Auto ক্যালকুলেট হবে।
... A23: বিস্তারিত ব্যবহারবিধির জন্য আলাদা 'ইউজার ম্যানুয়াল' ডকুমেন্টটি দেখুন — সেখানে প্রতিটা ধাপ উদাহরণসহ ব্যাখ্যা করা আছে।

Sheet Chart of Accounts
A1: হিসাব কোড (Account Code) | B1: হিসাবের নাম (Account Name) | C1: ধরন (Type) | D1: সেগমেন্ট (Segment) | E1: স্বাভাবিক ব্যালেন্স (Normal Balance)
A2: 1000 | B2: Cash in Hand | C2: Asset | D2: Shared | E2: Dr
A3: 1005 | B3: Petty Cash | C3: Asset | D3: Shared | E3: Dr
A4: 1010 | B4: Bank Account - Main | C4: Asset | D4: Shared | E4: Dr
A5: 1011 | B5: Bank Account - Secondary | C5: Asset | D5: Shared | E5: Dr
A6: 1020 | B6: L/C Margin Deposit | C6: Asset | D6: Import | E6: Dr
A7: 1100 | B7: Accounts Receivable - Local | C7: Asset | D7: Shared | E7: Dr
A8: 1101 | B8: Accounts Receivable - Export | C8: Asset | D8: Shared | E8: Dr
A9: 1110 | B9: Advance to Suppliers | C9: Asset | D9: Shared | E9: Dr
A10: 1120 | B10: Advance Income Tax (AIT) | C10: Asset | D10: Shared | E10: Dr
A11: 1130 | B11: VAT Current Account (Input VAT) | C11: Asset | D11: Shared | E11: Dr
A12: 1140 | B12: Advance to Employees | C12: Asset | D12: Shared | E12: Dr
A13: 1150 | B13: Prepaid Expenses | C13: Asset | D13: Shared | E13: Dr
... A90: 7020 | B90: Miscellaneous Income | C90: Other Income | D90: Shared | E90: Cr

Sheet Opening Balances
A1: শুরুর তারিখ (Cutover Date): | B1: 46266
A3: হিসাব কোড (Account Code) | B3: হিসাবের নাম (Account Name) | C3: প্রারম্ভিক ডেবিট (Opening Debit) | D3: প্রারম্ভিক ক্রেডিট (Opening Credit)
A4: 1010 | B4: {=IFERROR(INDEX('Chart of Accounts'!$B:$B,MATCH(A4,'Chart of Accounts'!$A:$A,0)),"")} -> Bank Account - Main | C4: 500000 | D4: 0
A5: 1200 | B5: {=IFERROR(INDEX('Chart of Accounts'!$B:$B,MATCH(A5,'Chart of Accounts'!$A:$A,0)),"")} -> Inventory - Imported Goods | C5: 100000 | D5: 0
A6: 1210 | B6: {=IFERROR(INDEX('Chart of Accounts'!$B:$B,MATCH(A6,'Chart of Accounts'!$A:$A,0)),"")} -> Inventory - Raw Materials | C6: 90000 | D6: 0
A7: 1240 | B7: {=IFERROR(INDEX('Chart of Accounts'!$B:$B,MATCH(A7,'Chart of Accounts'!$A:$A,0)),"")} -> Inventory - Packaging Materials | C7: 20000 | D7: 0
A8: 1250 | B8: {=IFERROR(INDEX('Chart of Accounts'!$B:$B,MATCH(A8,'Chart of Accounts'!$A:$A,0)),"")} -> Inventory - Trading Stock | C8: 90000 | D8: 0
A9: 3200 | B9: {=IFERROR(INDEX('Chart of Accounts'!$B:$B,MATCH(A9,'Chart of Accounts'!$A:$A,0)),"")} -> Opening Balance Equity | C9: 0 | D9: 800000
B11: মোট (TOTAL) | C11: =SUM(C4:C9) -> 800000 | D11: =SUM(D4:D9) -> 800000
B12: পার্থক্য (Difference) — অবশ্যই ০ হতে হবে | C12: =C11-D11 -> 0

Sheet Journal Entries
A1: ক্রমিক নং (SL) | B1: তারিখ (Date) | C1: ভাউচার নং (Voucher No) | D1: হিসাব কোড (Account Code) | E1: হিসাবের নাম (Account Name) | F1: সেগমেন্ট (Segment) | G1: ডেবিট (Debit) | H1: ক্রেডিট (Credit) | I1: বিবরণ (Narration) | J1: এন্ট্রিকারী (Entered By)
A2: 1 | B2: 46266 | C2: PROD-001 | D2: 1220 | E2: {=IFERROR(INDEX('Chart of Accounts'!$B:$B,MATCH(D2,'Chart of Accounts'!$A:$A,0)),"")} -> Inventory - WIP | F2: {=IFERROR(INDEX('Chart of Accounts'!$D:$D,MATCH(D2,'Chart of Accounts'!$A:$A,0)),"")} -> Manufacturing | G2: 12000 | I2: Production Order PROD-001: WIP001 output (RM001 + labor) | J2: Store
A3: 2 | B3: 46266 | C3: PROD-001 | D3: 1210 | E3: {=IFERROR(INDEX('Chart of Accounts'!$B:$B,MATCH(D3,'Chart of Accounts'!$A:$A,0)),"")} -> Inventory - Raw Materials | F3: {=IFERROR(INDEX('Chart of Accounts'!$D:$D,MATCH(D3,'Chart of Accounts'!$A:$A,0)),"")} -> Manufacturing | H3: 10000 | I3: Raw material RM001 consumed for PROD-001 | J3: Store
A4: 3 | B4: 46266 | C4: PROD-001 | D4: 1010 | E4: {=IFERROR(INDEX('Chart of Accounts'!$B:$B,MATCH(D4,'Chart of Accounts'!$A:$A,0)),"")} -> Bank Account - Main | F4: {=IFERROR(INDEX('Chart of Accounts'!$D:$D,MATCH(D4,'Chart of Accounts'!$A:$A,0)),"")} -> Shared | H4: 2000 | I4: Labor & OH paid for PROD-001 | J4: Store
A5: 4 | B5: 46266 | C5: PROD-002 | D5: 1220 | E5: {=IFERROR(INDEX('Chart of Accounts'!$B:$B,MATCH(D5,'Chart of Accounts'!$A:$A,0)),"")} -> Inventory - WIP | F5: {=IFERROR(INDEX('Chart of Accounts'!$D:$D,MATCH(D5,'Chart of Accounts'!$A:$A,0)),"")} -> Manufacturing | G5: 3000 | I5: Production Order PROD-002: WIP002 output (RM002 + labor added) | J5: Store
A6: 5 | B6: 46266 | C6: PROD-002 | D6: 1210 | E6: {=IFERROR(INDEX('Chart of Accounts'!$B:$B,MATCH(D6,'Chart of Accounts'!$A:$A,0)),"")} -> Inventory - Raw Materials | F6: {=IFERROR(INDEX('Chart of Accounts'!$D:$D,MATCH(D6,'Chart of Accounts'!$A:$A,0)),"")} -> Manufacturing | H6: 2000 | I6: Raw material RM002 consumed for PROD-002 | J6: Store
A7: 6 | B7: 46266 | C7: PROD-002 | D7: 1010 | E7: {=IFERROR(INDEX('Chart of Accounts'!$B:$B,MATCH(D7,'Chart of Accounts'!$A:$A,0)),"")} -> Bank Account - Main | F7: {=IFERROR(INDEX('Chart of Accounts'!$D:$D,MATCH(D7,'Chart of Accounts'!$A:$A,0)),"")} -> Shared | H7: 1000 | I7: Labor & OH paid for PROD-002 | J7: Store
A8: 7 | B8: 46266 | C8: PROD-003 | D8: 1230 | E8: {=IFERROR(INDEX('Chart of Accounts'!$B:$B,MATCH(D8,'Chart of Accounts'!$A:$A,0)),"")} -> Inventory - Finished Goods | F8: {=IFERROR(INDEX('Chart of Accounts'!$D:$D,MATCH(D8,'Chart of Accounts'!$A:$A,0)),"")} -> Manufacturing | G8: 4800 | I8: Production Order PROD-003: FG001 output (WIP002 + packaging + labor) | J8: Store
A9: 8 | B9: 46266 | C9: PROD-003 | D9: 1220 | E9: {=IFERROR(INDEX('Chart of Accounts'!$B:$B,MATCH(D9,'Chart of Accounts'!$A:$A,0)),"")} -> Inventory - WIP | F9: {=IFERROR(INDEX('Chart of Accounts'!$D:$D,MATCH(D9,'Chart of Accounts'!$A:$A,0)),"")} -> Manufacturing | H9: 3600 | I9: WIP002 consumed for PROD-003 | J9: Store
A10: 9 | B10: 46266 | C10: PROD-003 | D10: 1240 | E10: {=IFERROR(INDEX('Chart of Accounts'!$B:$B,MATCH(D10,'Chart of Accounts'!$A:$A,0)),"")} -> Inventory - Packaging Materials | F10: {=IFERROR(INDEX('Chart of Accounts'!$D:$D,MATCH(D10,'Chart of Accounts'!$A:$A,0)),"")} -> Packaging | H10: 400 | I10: Packaging (PKG001) consumed for PROD-003 | J10: Store
A11: 10 | B11: 46266 | C11: PROD-003 | D11: 1010 | E11: {=IFERROR(INDEX('Chart of Accounts'!$B:$B,MATCH(D11,'Chart of Accounts'!$A:$A,0)),"")} -> Bank Account - Main | F11: {=IFERROR(INDEX('Chart of Accounts'!$D:$D,MATCH(D11,'Chart of Accounts'!$A:$A,0)),"")} -> Shared | H11: 800 | I11: Labor & OH paid for PROD-003 | J11: Store
A12: 11 | B12: 46266 | C12: SALE-001 | D12: 1100 | E12: {=IFERROR(INDEX('Chart of Accounts'!$B:$B,MATCH(D12,'Chart of Accounts'!$A:$A,0)),"")} -> Accounts Receivable - Local | F12: {=IFERROR(INDEX('Chart of Accounts'!$D:$D,MATCH(D12,'Chart of Accounts'!$A:$A,0)),"")} -> Shared | G12: 4000 | I12: Sale of 10 units FG001 to customer | J12: Sales
A13: 12 | B13: 46266 | C13: SALE-001 | D13: 4010 | E13: {=IFERROR(INDEX('Chart of Accounts'!$B:$B,MATCH(D13,'Chart of Accounts'!$A:$A,0)),"")} -> Manufacturing Sales | F13: {=IFERROR(INDEX('Chart of Accounts'!$D:$D,MATCH(D13,'Chart of Accounts'!$A:$A,0)),"")} -> Manufacturing | H13: 4000 | I13: Sale of 10 units FG001 to customer | J13: Sales
A14: 13 | B14: 46266 | C14: SALE-001 | D14: 5010 | E14: {=IFERROR(INDEX('Chart of Accounts'!$B:$B,MATCH(D14,'Chart of Accounts'!$A:$A,0)),"")} -> COGS - Manufacturing (Raw Material Consumed) | F14: {=IFERROR(INDEX('Chart of Accounts'!$D:$D,MATCH(D14,'Chart of Accounts'!$A:$A,0)),"")} -> Manufacturing | G14: 2400 | I14: COGS for 10 units FG001 sold | J14: Sales
A15: 14 | B15: 46266 | C15: SALE-001 | D15: 1230 | E15: {=IFERROR(INDEX('Chart of Accounts'!$B:$B,MATCH(D15,'Chart of Accounts'!$A:$A,0)),"")} -> Inventory - Finished Goods | F15: {=IFERROR(INDEX('Chart of Accounts'!$D:$D,MATCH(D15,'Chart of Accounts'!$A:$A,0)),"")} -> Manufacturing | H15: 2400 | I15: Finished goods reduced for sale SALE-001 | J15: Sales
A16: =IF(B16="","",ROW()-1) | E16: {=IF(D16="","",IFERROR(INDEX('Chart of Accounts'!$B:$B,MATCH(D16,'Chart of Accounts'!$A:$A,0)),""))} | F16: {=IF(D16="","",IFERROR(INDEX('Chart of Accounts'!$D:$D,MATCH(D16,'Chart of Accounts'!$A:$A,0)),""))}
A17: =IF(B17="","",ROW()-1) | E17: {=IF(D17="","",IFERROR(INDEX('Chart of Accounts'!$B:$B,MATCH(D17,'Chart of Accounts'!$A:$A,0)),""))} | F17: {=IF(D17="","",IFERROR(INDEX('Chart of Accounts'!$D:$D,MATCH(D17,'Chart of Accounts'!$A:$A,0)),""))}
A18: =IF(B18="","",ROW()-1) | E18: {=IF(D18="","",IFERROR(INDEX('Chart of Accounts'!$B:$B,MATCH(D18,'Chart of Accounts'!$A:$A,0)),""))} | F18: {=IF(D18="","",IFERROR(INDEX('Chart of Accounts'!$D:$D,MATCH(D18,'Chart of Accounts'!$A:$A,0)),""))}
A19: =IF(B19="","",ROW()-1) | E19: {=IF(D19="","",IFERROR(INDEX('Chart of Accounts'!$B:$B,MATCH(D19,'Chart of Accounts'!$A:$A,0)),""))} | F19: {=IF(D19="","",IFERROR(INDEX('Chart of Accounts'!$D:$D,MATCH(D19,'Chart of Accounts'!$A:$A,0)),""))}
A20: =IF(B20="","",ROW()-1) | E20: {=IF(D20="","",IFERROR(INDEX('Chart of Accounts'!$B:$B,MATCH(D20,'Chart of Accounts'!$A:$A,0)),""))} | F20: {=IF(D20="","",IFERROR(INDEX('Chart of Accounts'!$D:$D,MATCH(D20,'Chart of Accounts'!$A:$A,0)),""))}
A21: =IF(B21="","",ROW()-1) | E21: {=IF(D21="","",IFERROR(INDEX('Chart of Accounts'!$B:$B,MATCH(D21,'Chart of Accounts'!$A:$A,0)),""))} | F21: {=IF(D21="","",IFERROR(INDEX('Chart of Accounts'!$D:$D,MATCH(D21,'Chart of Accounts'!$A:$A,0)),""))}
A22: =IF(B22="","",ROW()-1) | E22: {=IF(D22="","",IFERROR(INDEX('Chart of Accounts'!$B:$B,MATCH(D22,'Chart of Accounts'!$A:$A,0)),""))} | F22: {=IF(D22="","",IFERROR(INDEX('Chart of Accounts'!$D:$D,MATCH(D22,'Chart of Accounts'!$A:$A,0)),""))}
A23: =IF(B23="","",ROW()-1) | E23: {=IF(D23="","",IFERROR(INDEX('Chart of Accounts'!$B:$B,MATCH(D23,'Chart of Accounts'!$A:$A,0)),""))} | F23: {=IF(D23="","",IFERROR(INDEX('Chart of Accounts'!$D:$D,MATCH(D23,'Chart of Accounts'!$A:$A,0)),""))}
A24: =IF(B24="","",ROW()-1) | E24: {=IF(D24="","",IFERROR(INDEX('Chart of Accounts'!$B:$B,MATCH(D24,'Chart of Accounts'!$A:$A,0)),""))} | F24: {=IF(D24="","",IFERROR(INDEX('Chart of Accounts'!$D:$D,MATCH(D24,'Chart of Accounts'!$A:$A,0)),""))}
A25: =IF(B25="","",ROW()-1) | E25: {=IF(D25="","",IFERROR(INDEX('Chart of Accounts'!$B:$B,MATCH(D25,'Chart of Accounts'!$A:$A,0)),""))} | F25: {=IF(D25="","",IFERROR(INDEX('Chart of Accounts'!$D:$D,MATCH(D25,'Chart of Accounts'!$A:$A,0)),""))}
A26: =IF(B26="","",ROW()-1) | E26: {=IF(D26="","",IFERROR(INDEX('Chart of Accounts'!$B:$B,MATCH(D26,'Chart of Accounts'!$A:$A,0)),""))} | F26: {=IF(D26="","",IFERROR(INDEX('Chart of Accounts'!$D:$D,MATCH(D26,'Chart of Accounts'!$A:$A,0)),""))}
A27: =IF(B27="","",ROW()-1) | E27: {=IF(D27="","",IFERROR(INDEX('Chart of Accounts'!$B:$B,MATCH(D27,'Chart of Accounts'!$A:$A,0)),""))} | F27: {=IF(D27="","",IFERROR(INDEX('Chart of Accounts'!$D:$D,MATCH(D27,'Chart of Accounts'!$A:$A,0)),""))}
... A300: =IF(B300="","",ROW()-1) | E300: {=IF(D300="","",IFERROR(INDEX('Chart of Accounts'!$B:$B,MATCH(D300,'Chart of Accounts'!$A:$A,0)),""))} | F300: {=IF(D300="","",IFERROR(INDEX('Chart of Accounts'!$D:$D,MATCH(D300,'Chart of Accounts'!$A:$A,0)),""))}
F302: মোট (TOTAL) | G302: =SUM(G2:G300) -> 26200 | H302: =SUM(H2:H300) -> 26200
F303: পার্থক্য (Difference) — অবশ্যই ০ হতে হবে | G303: =G302-H302 -> 0

Sheet Item Master
A1: আইটেম কোড (Item Code) | B1: আইটেমের নাম (Item Name) | C1: ক্যাটাগরি (Category) | D1: সেগমেন্ট (Segment) | E1: একক (Unit) | F1: বর্তমান মজুদ পরিমাণ (Current Qty on Hand) | G1: বর্তমান গড় খরচ (Current Avg Cost)
A2: RM001 | B2: Raw Material A | C2: Raw Material | D2: Manufacturing | E2: kg | F2: =SUMIF('Inventory Ledger'!$B$2:$B$200,A2,'Inventory Ledger'!$F$2:$F$200)-SUMIF('Inventory Ledger'!$B$2:$B$200,A2,'Inventory Ledger'!$H$2:$H$200) -> 0 | G2: =IFERROR((SUMIF('Inventory Ledger'!$B$2:$B$200,A2,'Inventory Ledger'!$G$2:$G$200)-SUMIF('Inventory Ledger'!$B$2:$B$200,A2,'Inventory Ledger'!$I$2:$I$200))/F2,0) -> 0
A3: RM002 | B3: Raw Material B | C3: Raw Material | D3: Manufacturing | E3: kg | F3: =SUMIF('Inventory Ledger'!$B$2:$B$200,A3,'Inventory Ledger'!$F$2:$F$200)-SUMIF('Inventory Ledger'!$B$2:$B$200,A3,'Inventory Ledger'!$H$2:$H$200) -> 0 | G3: =IFERROR((SUMIF('Inventory Ledger'!$B$2:$B$200,A3,'Inventory Ledger'!$G$2:$G$200)-SUMIF('Inventory Ledger'!$B$2:$B$200,A3,'Inventory Ledger'!$I$2:$I$200))/F3,0) -> 0
A4: WIP001 | B4: Semi-Finished Stage 1 | C4: WIP | D4: Manufacturing | E4: pcs | F4: =SUMIF('Inventory Ledger'!$B$2:$B$200,A4,'Inventory Ledger'!$F$2:$F$200)-SUMIF('Inventory Ledger'!$B$2:$B$200,A4,'Inventory Ledger'!$H$2:$H$200) -> 0 | G4: =IFERROR((SUMIF('Inventory Ledger'!$B$2:$B$200,A4,'Inventory Ledger'!$G$2:$G$200)-SUMIF('Inventory Ledger'!$B$2:$B$200,A4,'Inventory Ledger'!$I$2:$I$200))/F4,0) -> 0
A5: WIP002 | B5: Semi-Finished Stage 2 | C5: WIP | D5: Manufacturing | E5: pcs | F5: =SUMIF('Inventory Ledger'!$B$2:$B$200,A5,'Inventory Ledger'!$F$2:$F$200)-SUMIF('Inventory Ledger'!$B$2:$B$200,A5,'Inventory Ledger'!$H$2:$H$200) -> 0 | G5: =IFERROR((SUMIF('Inventory Ledger'!$B$2:$B$200,A5,'Inventory Ledger'!$G$2:$G$200)-SUMIF('Inventory Ledger'!$B$2:$B$200,A5,'Inventory Ledger'!$I$2:$I$200))/F5,0) -> 0
A6: FG001 | B6: Finished Good X | C6: Finished Good | D6: Manufacturing | E6: pcs | F6: =SUMIF('Inventory Ledger'!$B$2:$B$200,A6,'Inventory Ledger'!$F$2:$F$200)-SUMIF('Inventory Ledger'!$B$2:$B$200,A6,'Inventory Ledger'!$H$2:$H$200) -> 0 | G6: =IFERROR((SUMIF('Inventory Ledger'!$B$2:$B$200,A6,'Inventory Ledger'!$G$2:$G$200)-SUMIF('Inventory Ledger'!$B$2:$B$200,A6,'Inventory Ledger'!$I$2:$I$200))/F6,0) -> 0
A7: PKG001 | B7: Packaging Box | C7: Packaging | D7: Packaging | E7: pcs | F7: =SUMIF('Inventory Ledger'!$B$2:$B$200,A7,'Inventory Ledger'!$F$2:$F$200)-SUMIF('Inventory Ledger'!$B$2:$B$200,A7,'Inventory Ledger'!$H$2:$H$200) -> 0 | G7: =IFERROR((SUMIF('Inventory Ledger'!$B$2:$B$200,A7,'Inventory Ledger'!$G$2:$G$200)-SUMIF('Inventory Ledger'!$B$2:$B$200,A7,'Inventory Ledger'!$I$2:$I$200))/F7,0) -> 0
A8: TRD001 | B8: Trading Item Y | C8: Trading Stock | D8: Trading | E8: pcs | F8: =SUMIF('Inventory Ledger'!$B$2:$B$200,A8,'Inventory Ledger'!$F$2:$F$200)-SUMIF('Inventory Ledger'!$B$2:$B$200,A8,'Inventory Ledger'!$H$2:$H$200) -> 0 | G8: =IFERROR((SUMIF('Inventory Ledger'!$B$2:$B$200,A8,'Inventory Ledger'!$G$2:$G$200)-SUMIF('Inventory Ledger'!$B$2:$B$200,A8,'Inventory Ledger'!$I$2:$I$200))/F8,0) -> 0
A9: IMP001 | B9: Imported Item Z | C9: Imported Goods | D9: Import | E9: pcs | F9: =SUMIF('Inventory Ledger'!$B$2:$B$200,A9,'Inventory Ledger'!$F$2:$F$200)-SUMIF('Inventory Ledger'!$B$2:$B$200,A9,'Inventory Ledger'!$H$2:$H$200) -> 0 | G9: =IFERROR((SUMIF('Inventory Ledger'!$B$2:$B$200,A9,'Inventory Ledger'!$G$2:$G$200)-SUMIF('Inventory Ledger'!$B$2:$B$200,A9,'Inventory Ledger'!$I$2:$I$200))/F9,0) -> 0
A10: RMC-001 | B10: Sand 30/80 | C10: Raw Material | D10: Manufacturing | E10: Kg | F10: =SUMIF('Inventory Ledger'!$B$2:$B$200,A10,'Inventory Ledger'!$F$2:$F$200)-SUMIF('Inventory Ledger'!$B$2:$B$200,A10,'Inventory Ledger'!$H$2:$H$200) -> 0 | G10: =IFERROR((SUMIF('Inventory Ledger'!$B$2:$B$200,A10,'Inventory Ledger'!$G$2:$G$200)-SUMIF('Inventory Ledger'!$B$2:$B$200,A10,'Inventory Ledger'!$I$2:$I$200))/F10,0) -> 0
A11: RMC-002 | B11: Lime 200 | C11: Raw Material | D11: Manufacturing | E11: Kg | F11: =SUMIF('Inventory Ledger'!$B$2:$B$200,A11,'Inventory Ledger'!$F$2:$F$200)-SUMIF('Inventory Ledger'!$B$2:$B$200,A11,'Inventory Ledger'!$H$2:$H$200) -> 0 | G11: =IFERROR((SUMIF('Inventory Ledger'!$B$2:$B$200,A11,'Inventory Ledger'!$G$2:$G$200)-SUMIF('Inventory Ledger'!$B$2:$B$200,A11,'Inventory Ledger'!$I$2:$I$200))/F11,0) -> 0
A12: RMC-003 | B12: Elephent Cement | C12: Raw Material | D12: Manufacturing | E12: Kg | F12: =SUMIF('Inventory Ledger'!$B$2:$B$200,A12,'Inventory Ledger'!$F$2:$F$200)-SUMIF('Inventory Ledger'!$B$2:$B$200,A12,'Inventory Ledger'!$H$2:$H$200) -> 790 | G12: =IFERROR((SUMIF('Inventory Ledger'!$B$2:$B$200,A12,'Inventory Ledger'!$G$2:$G$200)-SUMIF('Inventory Ledger'!$B$2:$B$200,A12,'Inventory Ledger'!$I$2:$I$200))/F12,0) -> 32.278481
A13: RMC-004 | B13: H.Lime | C13: Raw Material | D13: Manufacturing | E13: Kg | F13: =SUMIF('Inventory Ledger'!$B$2:$B$200,A13,'Inventory Ledger'!$F$2:$F$200)-SUMIF('Inventory Ledger'!$B$2:$B$200,A13,'Inventory Ledger'!$H$2:$H$200) -> 0 | G13: =IFERROR((SUMIF('Inventory Ledger'!$B$2:$B$200,A13,'Inventory Ledger'!$G$2:$G$200)-SUMIF('Inventory Ledger'!$B$2:$B$200,A13,'Inventory Ledger'!$I$2:$I$200))/F13,0) -> 0
... A44: PKD-035 | B44: Color Cartoon | C44: Packaging | D44: Packaging | E44: Pcs | F44: =SUMIF('Inventory Ledger'!$B$2:$B$200,A44,'Inventory Ledger'!$F$2:$F$200)-SUMIF('Inventory Ledger'!$B$2:$B$200,A44,'Inventory Ledger'!$H$2:$H$200) -> 0 | G44: =IFERROR((SUMIF('Inventory Ledger'!$B$2:$B$200,A44,'Inventory Ledger'!$G$2:$G$200)-SUMIF('Inventory Ledger'!$B$2:$B$200,A44,'Inventory Ledger'!$I$2:$I$200))/F44,0) -> 0

Sheet BOM Master
A1: মূল আইটেম কোড (Parent Item Code) | B1: মূল আইটেমের নাম (Parent Item Name) | C1: ধাপ (Stage) | D1: উপকরণ আইটেম কোড (Component Item Code) | E1: উপকরণের নাম (Component Name) | F1: প্রতি ইউনিটে পরিমাণ (Qty per Unit) | G1: একক (Unit)
A2: TRD-018 | B2: {=IFERROR(INDEX('Item Master'!$B:$B,MATCH(A2,'Item Master'!$A:$A,0)),"")} -> NovaCrete PU-MF-C-Filler | C2: 1 | D2: RMC-001 | E2: {=IFERROR(INDEX('Item Master'!$B:$B,MATCH(D2,'Item Master'!$A:$A,0)),"")} -> Sand 30/80 | F2: 6 | G2: {=IFERROR(INDEX('Item Master'!$E:$E,MATCH(D2,'Item Master'!$A:$A,0)),"")} -> Kg
A3: TRD-018 | B3: {=IFERROR(INDEX('Item Master'!$B:$B,MATCH(A3,'Item Master'!$A:$A,0)),"")} -> NovaCrete PU-MF-C-Filler | C3: 2 | D3: RMC-002 | E3: {=IFERROR(INDEX('Item Master'!$B:$B,MATCH(D3,'Item Master'!$A:$A,0)),"")} -> Lime 200 | F3: 1 | G3: {=IFERROR(INDEX('Item Master'!$E:$E,MATCH(D3,'Item Master'!$A:$A,0)),"")} -> Kg
A4: TRD-018 | B4: {=IFERROR(INDEX('Item Master'!$B:$B,MATCH(A4,'Item Master'!$A:$A,0)),"")} -> NovaCrete PU-MF-C-Filler | C4: 3 | D4: RMC-003 | E4: {=IFERROR(INDEX('Item Master'!$B:$B,MATCH(D4,'Item Master'!$A:$A,0)),"")} -> Elephent Cement | F4: 4.2 | G4: {=IFERROR(INDEX('Item Master'!$E:$E,MATCH(D4,'Item Master'!$A:$A,0)),"")} -> Kg
A5: TRD-018 | B5: {=IFERROR(INDEX('Item Master'!$B:$B,MATCH(A5,'Item Master'!$A:$A,0)),"")} -> NovaCrete PU-MF-C-Filler | C5: 4 | D5: RMC-004 | E5: {=IFERROR(INDEX('Item Master'!$B:$B,MATCH(D5,'Item Master'!$A:$A,0)),"")} -> H.Lime | F5: 2 | G5: {=IFERROR(INDEX('Item Master'!$E:$E,MATCH(D5,'Item Master'!$A:$A,0)),"")} -> Kg
A6: TRD-018 | B6: {=IFERROR(INDEX('Item Master'!$B:$B,MATCH(A6,'Item Master'!$A:$A,0)),"")} -> NovaCrete PU-MF-C-Filler | C6: 5 | D6: RMCD-005 | E6: {=IFERROR(INDEX('Item Master'!$B:$B,MATCH(D6,'Item Master'!$A:$A,0)),"")} -> T2 C/D | F6: 1 | G6: {=IFERROR(INDEX('Item Master'!$E:$E,MATCH(D6,'Item Master'!$A:$A,0)),"")} -> Kg
A7: TRD-018 | B7: {=IFERROR(INDEX('Item Master'!$B:$B,MATCH(A7,'Item Master'!$A:$A,0)),"")} -> NovaCrete PU-MF-C-Filler | C7: 6 | D7: PKC-026 | E7: {=IFERROR(INDEX('Item Master'!$B:$B,MATCH(D7,'Item Master'!$A:$A,0)),"")} -> Filler Bag C Printed | F7: 1 | G7: {=IFERROR(INDEX('Item Master'!$E:$E,MATCH(D7,'Item Master'!$A:$A,0)),"")} -> Pcs.
B8: {=IFERROR(INDEX('Item Master'!$B:$B,MATCH(A8,'Item Master'!$A:$A,0)),"")}
B9: {=IFERROR(INDEX('Item Master'!$B:$B,MATCH(A9,'Item Master'!$A:$A,0)),"")}
B10: {=IFERROR(INDEX('Item Master'!$B:$B,MATCH(A10,'Item Master'!$A:$A,0)),"")}
B11: {=IFERROR(INDEX('Item Master'!$B:$B,MATCH(A11,'Item Master'!$A:$A,0)),"")}
B12: {=IFERROR(INDEX('Item Master'!$B:$B,MATCH(A12,'Item Master'!$A:$A,0)),"")}
B13: {=IFERROR(INDEX('Item Master'!$B:$B,MATCH(A13,'Item Master'!$A:$A,0)),"")}
B14: {=IFERROR(INDEX('Item Master'!$B:$B,MATCH(A14,'Item Master'!$A:$A,0)),"")}
B15: {=IFERROR(INDEX('Item Master'!$B:$B,MATCH(A15,'Item Master'!$A:$A,0)),"")}
B16: {=IFERROR(INDEX('Item Master'!$B:$B,MATCH(A16,'Item Master'!$A:$A,0)),"")}
B17: {=IFERROR(INDEX('Item Master'!$B:$B,MATCH(A17,'Item Master'!$A:$A,0)),"")}
B18: {=IFERROR(INDEX('Item Master'!$B:$B,MATCH(A18,'Item Master'!$A:$A,0)),"")}
B19: {=IFERROR(INDEX('Item Master'!$B:$B,MATCH(A19,'Item Master'!$A:$A,0)),"")}
... B24: {=IFERROR(INDEX('Item Master'!$B:$B,MATCH(A24,'Item Master'!$A:$A,0)),"")}

Sheet Production Entry
A1: তারিখ (Date) | B1: অর্ডার নং (Order No) | C1: উৎপাদিত আইটেম (Item Produced) | D1: আইটেমের নাম (Item Name) | E1: উৎপাদিত পরিমাণ (Qty Produced) | F1: উপকরণ কোড (Component Code) | G1: উপকরণের নাম (Component Name) | H1: প্রতি ইউনিটে পরিমাণ (Qty per Unit) | I1: ব্যবহৃত পরিমাণ (Qty Consumed) | J1: উপকরণের গড় খরচ (Component Avg Cost) | K1: উপকরণ খরচ (Component Cost) | L1: শ্রম ও ওভারহেড খরচ (Labor & Overhead) | M1: অর্ডারের কাঁচামাল খরচ (Order Material Cost) | N1: অর্ডারের শ্রম+ওভারহেড (Order Labor+OH) | O1: অর্ডারের মোট খরচ (Order Total Cost) | P1: উৎপাদিত পণ্যের ইউনিট খরচ (Unit Cost of Output)
A2: 46266 | B2: PROD-001 | C2: WIP001 | D2: {=IF(C2="","",IFERROR(INDEX('Item Master'!$B:$B,MATCH(C2,'Item Master'!$A:$A,0)),""))} -> Semi-Finished Stage 1 | F2: RM001 | G2: {=IF(F2="","",IFERROR(INDEX('Item Master'!$B:$B,MATCH(F2,'Item Master'!$A:$A,0)),""))} -> Raw Material A | H2: =IF(F2="",0,SUMIFS('BOM Master'!$F:$F,'BOM Master'!$A:$A,C2,'BOM Master'!$D:$D,F2)) -> 0 | I2: =E2*H2 -> 0 | J2: {=IF(F2="",0,IFERROR(INDEX('Item Master'!$G:$G,MATCH(F2,'Item Master'!$A:$A,0)),0))} -> 0 | K2: =I2*J2 -> 0 | M2: =IF(B2="","",SUMIF($B$2:$B$150,B2,$K$2:$K$150)) -> 0 | N2: =IF(B2="","",SUMIF($B$2:$B$150,B2,$L$2:$L$150)) -> 0 | O2: =IF(B2="","",M2+N2) -> 0 | P2: =IF(B2="","",IFERROR(O2/E2,0)) -> 0
A3: 46266 | B3: PROD-002 | C3: WIP002 | D3: {=IF(C3="","",IFERROR(INDEX('Item Master'!$B:$B,MATCH(C3,'Item Master'!$A:$A,0)),""))} -> Semi-Finished Stage 2 | F3: WIP001 | G3: {=IF(F3="","",IFERROR(INDEX('Item Master'!$B:$B,MATCH(F3,'Item Master'!$A:$A,0)),""))} -> Semi-Finished Stage 1 | H3: =IF(F3="",0,SUMIFS('BOM Master'!$F:$F,'BOM Master'!$A:$A,C3,'BOM Master'!$D:$D,F3)) -> 0 | I3: =E3*H3 -> 0 | J3: {=IF(F3="",0,IFERROR(INDEX('Item Master'!$G:$G,MATCH(F3,'Item Master'!$A:$A,0)),0))} -> 0 | K3: =I3*J3 -> 0 | M3: =IF(B3="","",SUMIF($B$2:$B$150,B3,$K$2:$K$150)) -> 0 | N3: =IF(B3="","",SUMIF($B$2:$B$150,B3,$L$2:$L$150)) -> 0 | O3: =IF(B3="","",M3+N3) -> 0 | P3: =IF(B3="","",IFERROR(O3/E3,0)) -> 0
A4: 46266 | B4: PROD-002 | C4: WIP002 | D4: {=IF(C4="","",IFERROR(INDEX('Item Master'!$B:$B,MATCH(C4,'Item Master'!$A:$A,0)),""))} -> Semi-Finished Stage 2 | F4: RM002 | G4: {=IF(F4="","",IFERROR(INDEX('Item Master'!$B:$B,MATCH(F4,'Item Master'!$A:$A,0)),""))} -> Raw Material B | H4: =IF(F4="",0,SUMIFS('BOM Master'!$F:$F,'BOM Master'!$A:$A,C4,'BOM Master'!$D:$D,F4)) -> 0 | I4: =E4*H4 -> 0 | J4: {=IF(F4="",0,IFERROR(INDEX('Item Master'!$G:$G,MATCH(F4,'Item Master'!$A:$A,0)),0))} -> 0 | K4: =I4*J4 -> 0 | M4: =IF(B4="","",SUMIF($B$2:$B$150,B4,$K$2:$K$150)) -> 0 | N4: =IF(B4="","",SUMIF($B$2:$B$150,B4,$L$2:$L$150)) -> 0 | O4: =IF(B4="","",M4+N4) -> 0 | P4: =IF(B4="","",IFERROR(O4/E4,0)) -> 0
A5: 46266 | B5: PROD-003 | C5: FG001 | D5: {=IF(C5="","",IFERROR(INDEX('Item Master'!$B:$B,MATCH(C5,'Item Master'!$A:$A,0)),""))} -> Finished Good X | F5: WIP002 | G5: {=IF(F5="","",IFERROR(INDEX('Item Master'!$B:$B,MATCH(F5,'Item Master'!$A:$A,0)),""))} -> Semi-Finished Stage 2 | H5: =IF(F5="",0,SUMIFS('BOM Master'!$F:$F,'BOM Master'!$A:$A,C5,'BOM Master'!$D:$D,F5)) -> 0 | I5: =E5*H5 -> 0 | J5: {=IF(F5="",0,IFERROR(INDEX('Item Master'!$G:$G,MATCH(F5,'Item Master'!$A:$A,0)),0))} -> 0 | K5: =I5*J5 -> 0 | M5: =IF(B5="","",SUMIF($B$2:$B$150,B5,$K$2:$K$150)) -> 0 | N5: =IF(B5="","",SUMIF($B$2:$B$150,B5,$L$2:$L$150)) -> 0 | O5: =IF(B5="","",M5+N5) -> 0 | P5: =IF(B5="","",IFERROR(O5/E5,0)) -> 0
A6: 46266 | B6: PROD-003 | C6: FG001 | D6: {=IF(C6="","",IFERROR(INDEX('Item Master'!$B:$B,MATCH(C6,'Item Master'!$A:$A,0)),""))} -> Finished Good X | F6: PKG001 | G6: {=IF(F6="","",IFERROR(INDEX('Item Master'!$B:$B,MATCH(F6,'Item Master'!$A:$A,0)),""))} -> Packaging Box | H6: =IF(F6="",0,SUMIFS('BOM Master'!$F:$F,'BOM Master'!$A:$A,C6,'BOM Master'!$D:$D,F6)) -> 0 | I6: =E6*H6 -> 0 | J6: {=IF(F6="",0,IFERROR(INDEX('Item Master'!$G:$G,MATCH(F6,'Item Master'!$A:$A,0)),0))} -> 0 | K6: =I6*J6 -> 0 | M6: =IF(B6="","",SUMIF($B$2:$B$150,B6,$K$2:$K$150)) -> 0 | N6: =IF(B6="","",SUMIF($B$2:$B$150,B6,$L$2:$L$150)) -> 0 | O6: =IF(B6="","",M6+N6) -> 0 | P6: =IF(B6="","",IFERROR(O6/E6,0)) -> 0
C7: TRD-018 | D7: {=IF(C7="","",IFERROR(INDEX('Item Master'!$B:$B,MATCH(C7,'Item Master'!$A:$A,0)),""))} -> NovaCrete PU-MF-C-Filler | E7: 50 | F7: RMC-003 | G7: {=IF(F7="","",IFERROR(INDEX('Item Master'!$B:$B,MATCH(F7,'Item Master'!$A:$A,0)),""))} -> Elephent Cement | H7: =IF(F7="",0,SUMIFS('BOM Master'!$F:$F,'BOM Master'!$A:$A,C7,'BOM Master'!$D:$D,F7)) -> 4.2 | I7: =E7*H7 -> 210 | J7: {=IF(F7="",0,IFERROR(INDEX('Item Master'!$G:$G,MATCH(F7,'Item Master'!$A:$A,0)),0))} -> 32.278481 | K7: =I7*J7 -> 6778.481 | L7: 100 | M7: =IF(B7="","",SUMIF($B$2:$B$150,B7,$K$2:$K$150)) | N7: =IF(B7="","",SUMIF($B$2:$B$150,B7,$L$2:$L$150)) | O7: =IF(B7="","",M7+N7) | P7: =IF(B7="","",IFERROR(O7/E7,0))
D8: {=IF(C8="","",IFERROR(INDEX('Item Master'!$B:$B,MATCH(C8,'Item Master'!$A:$A,0)),""))} | G8: {=IF(F8="","",IFERROR(INDEX('Item Master'!$B:$B,MATCH(F8,'Item Master'!$A:$A,0)),""))} | H8: =IF(F8="",0,SUMIFS('BOM Master'!$F:$F,'BOM Master'!$A:$A,C8,'BOM Master'!$D:$D,F8)) -> 0 | I8: =E8*H8 -> 0 | J8: {=IF(F8="",0,IFERROR(INDEX('Item Master'!$G:$G,MATCH(F8,'Item Master'!$A:$A,0)),0))} -> 0 | K8: =I8*J8 -> 0 | M8: =IF(B8="","",SUMIF($B$2:$B$150,B8,$K$2:$K$150)) | N8: =IF(B8="","",SUMIF($B$2:$B$150,B8,$L$2:$L$150)) | O8: =IF(B8="","",M8+N8) | P8: =IF(B8="","",IFERROR(O8/E8,0))
D9: {=IF(C9="","",IFERROR(INDEX('Item Master'!$B:$B,MATCH(C9,'Item Master'!$A:$A,0)),""))} | G9: {=IF(F9="","",IFERROR(INDEX('Item Master'!$B:$B,MATCH(F9,'Item Master'!$A:$A,0)),""))} | H9: =IF(F9="",0,SUMIFS('BOM Master'!$F:$F,'BOM Master'!$A:$A,C9,'BOM Master'!$D:$D,F9)) -> 0 | I9: =E9*H9 -> 0 | J9: {=IF(F9="",0,IFERROR(INDEX('Item Master'!$G:$G,MATCH(F9,'Item Master'!$A:$A,0)),0))} -> 0 | K9: =I9*J9 -> 0 | M9: =IF(B9="","",SUMIF($B$2:$B$150,B9,$K$2:$K$150)) | N9: =IF(B9="","",SUMIF($B$2:$B$150,B9,$L$2:$L$150)) | O9: =IF(B9="","",M9+N9) | P9: =IF(B9="","",IFERROR(O9/E9,0))
D10: {=IF(C10="","",IFERROR(INDEX('Item Master'!$B:$B,MATCH(C10,'Item Master'!$A:$A,0)),""))} | G10: {=IF(F10="","",IFERROR(INDEX('Item Master'!$B:$B,MATCH(F10,'Item Master'!$A:$A,0)),""))} | H10: =IF(F10="",0,SUMIFS('BOM Master'!$F:$F,'BOM Master'!$A:$A,C10,'BOM Master'!$D:$D,F10)) -> 0 | I10: =E10*H10 -> 0 | J10: {=IF(F10="",0,IFERROR(INDEX('Item Master'!$G:$G,MATCH(F10,'Item Master'!$A:$A,0)),0))} -> 0 | K10: =I10*J10 -> 0 | M10: =IF(B10="","",SUMIF($B$2:$B$150,B10,$K$2:$K$150)) | N10: =IF(B10="","",SUMIF($B$2:$B$150,B10,$L$2:$L$150)) | O10: =IF(B10="","",M10+N10) | P10: =IF(B10="","",IFERROR(O10/E10,0))
D11: {=IF(C11="","",IFERROR(INDEX('Item Master'!$B:$B,MATCH(C11,'Item Master'!$A:$A,0)),""))} | G11: {=IF(F11="","",IFERROR(INDEX('Item Master'!$B:$B,MATCH(F11,'Item Master'!$A:$A,0)),""))} | H11: =IF(F11="",0,SUMIFS('BOM Master'!$F:$F,'BOM Master'!$A:$A,C11,'BOM Master'!$D:$D,F11)) -> 0 | I11: =E11*H11 -> 0 | J11: {=IF(F11="",0,IFERROR(INDEX('Item Master'!$G:$G,MATCH(F11,'Item Master'!$A:$A,0)),0))} -> 0 | K11: =I11*J11 -> 0 | M11: =IF(B11="","",SUMIF($B$2:$B$150,B11,$K$2:$K$150)) | N11: =IF(B11="","",SUMIF($B$2:$B$150,B11,$L$2:$L$150)) | O11: =IF(B11="","",M11+N11) | P11: =IF(B11="","",IFERROR(O11/E11,0))
D12: {=IF(C12="","",IFERROR(INDEX('Item Master'!$B:$B,MATCH(C12,'Item Master'!$A:$A,0)),""))} | G12: {=IF(F12="","",IFERROR(INDEX('Item Master'!$B:$B,MATCH(F12,'Item Master'!$A:$A,0)),""))} | H12: =IF(F12="",0,SUMIFS('BOM Master'!$F:$F,'BOM Master'!$A:$A,C12,'BOM Master'!$D:$D,F12)) -> 0 | I12: =E12*H12 -> 0 | J12: {=IF(F12="",0,IFERROR(INDEX('Item Master'!$G:$G,MATCH(F12,'Item Master'!$A:$A,0)),0))} -> 0 | K12: =I12*J12 -> 0 | M12: =IF(B12="","",SUMIF($B$2:$B$150,B12,$K$2:$K$150)) | N12: =IF(B12="","",SUMIF($B$2:$B$150,B12,$L$2:$L$150)) | O12: =IF(B12="","",M12+N12) | P12: =IF(B12="","",IFERROR(O12/E12,0))
D13: {=IF(C13="","",IFERROR(INDEX('Item Master'!$B:$B,MATCH(C13,'Item Master'!$A:$A,0)),""))} | G13: {=IF(F13="","",IFERROR(INDEX('Item Master'!$B:$B,MATCH(F13,'Item Master'!$A:$A,0)),""))} | H13: =IF(F13="",0,SUMIFS('BOM Master'!$F:$F,'BOM Master'!$A:$A,C13,'BOM Master'!$D:$D,F13)) -> 0 | I13: =E13*H13 -> 0 | J13: {=IF(F13="",0,IFERROR(INDEX('Item Master'!$G:$G,MATCH(F13,'Item Master'!$A:$A,0)),0))} -> 0 | K13: =I13*J13 -> 0 | M13: =IF(B13="","",SUMIF($B$2:$B$150,B13,$K$2:$K$150)) | N13: =IF(B13="","",SUMIF($B$2:$B$150,B13,$L$2:$L$150)) | O13: =IF(B13="","",M13+N13) | P13: =IF(B13="","",IFERROR(O13/E13,0))
D14: {=IF(C14="","",IFERROR(INDEX('Item Master'!$B:$B,MATCH(C14,'Item Master'!$A:$A,0)),""))} | G14: {=IF(F14="","",IFERROR(INDEX('Item Master'!$B:$B,MATCH(F14,'Item Master'!$A:$A,0)),""))} | H14: =IF(F14="",0,SUMIFS('BOM Master'!$F:$F,'BOM Master'!$A:$A,C14,'BOM Master'!$D:$D,F14)) -> 0 | I14: =E14*H14 -> 0 | J14: {=IF(F14="",0,IFERROR(INDEX('Item Master'!$G:$G,MATCH(F14,'Item Master'!$A:$A,0)),0))} -> 0 | K14: =I14*J14 -> 0 | M14: =IF(B14="","",SUMIF($B$2:$B$150,B14,$K$2:$K$150)) | N14: =IF(B14="","",SUMIF($B$2:$B$150,B14,$L$2:$L$150)) | O14: =IF(B14="","",M14+N14) | P14: =IF(B14="","",IFERROR(O14/E14,0))
D15: {=IF(C15="","",IFERROR(INDEX('Item Master'!$B:$B,MATCH(C15,'Item Master'!$A:$A,0)),""))} | G15: {=IF(F15="","",IFERROR(INDEX('Item Master'!$B:$B,MATCH(F15,'Item Master'!$A:$A,0)),""))} | H15: =IF(F15="",0,SUMIFS('BOM Master'!$F:$F,'BOM Master'!$A:$A,C15,'BOM Master'!$D:$D,F15)) -> 0 | I15: =E15*H15 -> 0 | J15: {=IF(F15="",0,IFERROR(INDEX('Item Master'!$G:$G,MATCH(F15,'Item Master'!$A:$A,0)),0))} -> 0 | K15: =I15*J15 -> 0 | M15: =IF(B15="","",SUMIF($B$2:$B$150,B15,$K$2:$K$150)) | N15: =IF(B15="","",SUMIF($B$2:$B$150,B15,$L$2:$L$150)) | O15: =IF(B15="","",M15+N15) | P15: =IF(B15="","",IFERROR(O15/E15,0))
D16: {=IF(C16="","",IFERROR(INDEX('Item Master'!$B:$B,MATCH(C16,'Item Master'!$A:$A,0)),""))} | G16: {=IF(F16="","",IFERROR(INDEX('Item Master'!$B:$B,MATCH(F16,'Item Master'!$A:$A,0)),""))} | H16: =IF(F16="",0,SUMIFS('BOM Master'!$F:$F,'BOM Master'!$A:$A,C16,'BOM Master'!$D:$D,F16)) -> 0 | I16: =E16*H16 -> 0 | J16: {=IF(F16="",0,IFERROR(INDEX('Item Master'!$G:$G,MATCH(F16,'Item Master'!$A:$A,0)),0))} -> 0 | K16: =I16*J16 -> 0 | M16: =IF(B16="","",SUMIF($B$2:$B$150,B16,$K$2:$K$150)) | N16: =IF(B16="","",SUMIF($B$2:$B$150,B16,$L$2:$L$150)) | O16: =IF(B16="","",M16+N16) | P16: =IF(B16="","",IFERROR(O16/E16,0))
D17: {=IF(C17="","",IFERROR(INDEX('Item Master'!$B:$B,MATCH(C17,'Item Master'!$A:$A,0)),""))} | G17: {=IF(F17="","",IFERROR(INDEX('Item Master'!$B:$B,MATCH(F17,'Item Master'!$A:$A,0)),""))} | H17: =IF(F17="",0,SUMIFS('BOM Master'!$F:$F,'BOM Master'!$A:$A,C17,'BOM Master'!$D:$D,F17)) -> 0 | I17: =E17*H17 -> 0 | J17: {=IF(F17="",0,IFERROR(INDEX('Item Master'!$G:$G,MATCH(F17,'Item Master'!$A:$A,0)),0))} -> 0 | K17: =I17*J17 -> 0 | M17: =IF(B17="","",SUMIF($B$2:$B$150,B17,$K$2:$K$150)) | N17: =IF(B17="","",SUMIF($B$2:$B$150,B17,$L$2:$L$150)) | O17: =IF(B17="","",M17+N17) | P17: =IF(B17="","",IFERROR(O17/E17,0))
D18: {=IF(C18="","",IFERROR(INDEX('Item Master'!$B:$B,MATCH(C18,'Item Master'!$A:$A,0)),""))} | G18: {=IF(F18="","",IFERROR(INDEX('Item Master'!$B:$B,MATCH(F18,'Item Master'!$A:$A,0)),""))} | H18: =IF(F18="",0,SUMIFS('BOM Master'!$F:$F,'BOM Master'!$A:$A,C18,'BOM Master'!$D:$D,F18)) -> 0 | I18: =E18*H18 -> 0 | J18: {=IF(F18="",0,IFERROR(INDEX('Item Master'!$G:$G,MATCH(F18,'Item Master'!$A:$A,0)),0))} -> 0 | K18: =I18*J18 -> 0 | M18: =IF(B18="","",SUMIF($B$2:$B$150,B18,$K$2:$K$150)) | N18: =IF(B18="","",SUMIF($B$2:$B$150,B18,$L$2:$L$150)) | O18: =IF(B18="","",M18+N18) | P18: =IF(B18="","",IFERROR(O18/E18,0))
D19: {=IF(C19="","",IFERROR(INDEX('Item Master'!$B:$B,MATCH(C19,'Item Master'!$A:$A,0)),""))} | G19: {=IF(F19="","",IFERROR(INDEX('Item Master'!$B:$B,MATCH(F19,'Item Master'!$A:$A,0)),""))} | H19: =IF(F19="",0,SUMIFS('BOM Master'!$F:$F,'BOM Master'!$A:$A,C19,'BOM Master'!$D:$D,F19)) -> 0 | I19: =E19*H19 -> 0 | J19: {=IF(F19="",0,IFERROR(INDEX('Item Master'!$G:$G,MATCH(F19,'Item Master'!$A:$A,0)),0))} -> 0 | K19: =I19*J19 -> 0 | M19: =IF(B19="","",SUMIF($B$2:$B$150,B19,$K$2:$K$150)) | N19: =IF(B19="","",SUMIF($B$2:$B$150,B19,$L$2:$L$150)) | O19: =IF(B19="","",M19+N19) | P19: =IF(B19="","",IFERROR(O19/E19,0))
... D150: {=IF(C150="","",IFERROR(INDEX('Item Master'!$B:$B,MATCH(C150,'Item Master'!$A:$A,0)),""))} | G150: {=IF(F150="","",IFERROR(INDEX('Item Master'!$B:$B,MATCH(F150,'Item Master'!$A:$A,0)),""))} | H150: =IF(F150="",0,SUMIFS('BOM Master'!$F:$F,'BOM Master'!$A:$A,C150,'BOM Master'!$D:$D,F150)) -> 0 | I150: =E150*H150 -> 0 | J150: {=IF(F150="",0,IFERROR(INDEX('Item Master'!$G:$G,MATCH(F150,'Item Master'!$A:$A,0)),0))} -> 0 | K150: =I150*J150 -> 0 | M150: =IF(B150="","",SUMIF($B$2:$B$150,B150,$K$2:$K$150)) | N150: =IF(B150="","",SUMIF($B$2:$B$150,B150,$L$2:$L$150)) | O150: =IF(B150="","",M150+N150) | P150: =IF(B150="","",IFERROR(O150/E150,0))

Sheet Inventory Ledger
A1: তারিখ (Date) | B1: আইটেম কোড (Item Code) | C1: আইটেমের নাম (Item Name) | D1: লেনদেনের ধরন (Txn Type) | E1: রেফারেন্স নং (Reference No) | F1: ইন পরিমাণ (In Qty) | G1: ইন মূল্য (In Value) | H1: আউট পরিমাণ (Out Qty) | I1: আউট মূল্য (Out Value) | J1: প্রস্তাবিত আউট মূল্য (Suggested Out Value) | K1: স্থিতি পরিমাণ (Balance Qty) | L1: স্থিতি মূল্য (Balance Value) | M1: গড় খরচ (Avg Cost)
A2: 46266 | B2: RM001 | C2: {=IFERROR(INDEX('Item Master'!$B:$B,MATCH(B2,'Item Master'!$A:$A,0)),"")} -> Raw Material A | D2: Opening Stock | E2: OPEN-01 | J2: =IFERROR(H2*(SUMIFS($G$1:G1,$B$1:B1,B2)-SUMIFS($I$1:I1,$B$1:B1,B2))/(SUMIFS($F$1:F1,$B$1:B1,B2)-SUMIFS($H$1:H1,$B$1:B1,B2)),0) -> 0 | K2: =IF(B2="","",SUMIFS($F$2:F2,$B$2:B2,B2)-SUMIFS($H$2:H2,$B$2:B2,B2)) -> 0 | L2: =IF(B2="","",SUMIFS($G$2:G2,$B$2:B2,B2)-SUMIFS($I$2:I2,$B$2:B2,B2)) -> 0 | M2: =IFERROR(L2/K2,0) -> 0
A3: 46266 | B3: RM002 | C3: {=IFERROR(INDEX('Item Master'!$B:$B,MATCH(B3,'Item Master'!$A:$A,0)),"")} -> Raw Material B | D3: Opening Stock | E3: OPEN-01 | J3: =IFERROR(H3*(SUMIFS($G$1:G2,$B$1:B2,B3)-SUMIFS($I$1:I2,$B$1:B2,B3))/(SUMIFS($F$1:F2,$B$1:B2,B3)-SUMIFS($H$1:H2,$B$1:B2,B3)),0) -> 0 | K3: =IF(B3="","",SUMIFS($F$2:F3,$B$2:B3,B3)-SUMIFS($H$2:H3,$B$2:B3,B3)) -> 0 | L3: =IF(B3="","",SUMIFS($G$2:G3,$B$2:B3,B3)-SUMIFS($I$2:I3,$B$2:B3,B3)) -> 0 | M3: =IFERROR(L3/K3,0) -> 0
A4: 46266 | B4: PKG001 | C4: {=IFERROR(INDEX('Item Master'!$B:$B,MATCH(B4,'Item Master'!$A:$A,0)),"")} -> Packaging Box | D4: Opening Stock | E4: OPEN-01 | J4: =IFERROR(H4*(SUMIFS($G$1:G3,$B$1:B3,B4)-SUMIFS($I$1:I3,$B$1:B3,B4))/(SUMIFS($F$1:F3,$B$1:B3,B4)-SUMIFS($H$1:H3,$B$1:B3,B4)),0) -> 0 | K4: =IF(B4="","",SUMIFS($F$2:F4,$B$2:B4,B4)-SUMIFS($H$2:H4,$B$2:B4,B4)) -> 0 | L4: =IF(B4="","",SUMIFS($G$2:G4,$B$2:B4,B4)-SUMIFS($I$2:I4,$B$2:B4,B4)) -> 0 | M4: =IFERROR(L4/K4,0) -> 0
A5: 46266 | B5: TRD001 | C5: {=IFERROR(INDEX('Item Master'!$B:$B,MATCH(B5,'Item Master'!$A:$A,0)),"")} -> Trading Item Y | D5: Opening Stock | E5: OPEN-01 | J5: =IFERROR(H5*(SUMIFS($G$1:G4,$B$1:B4,B5)-SUMIFS($I$1:I4,$B$1:B4,B5))/(SUMIFS($F$1:F4,$B$1:B4,B5)-SUMIFS($H$1:H4,$B$1:B4,B5)),0) -> 0 | K5: =IF(B5="","",SUMIFS($F$2:F5,$B$2:B5,B5)-SUMIFS($H$2:H5,$B$2:B5,B5)) -> 0 | L5: =IF(B5="","",SUMIFS($G$2:G5,$B$2:B5,B5)-SUMIFS($I$2:I5,$B$2:B5,B5)) -> 0 | M5: =IFERROR(L5/K5,0) -> 0
A6: 46266 | B6: IMP001 | C6: {=IFERROR(INDEX('Item Master'!$B:$B,MATCH(B6,'Item Master'!$A:$A,0)),"")} -> Imported Item Z | D6: Opening Stock | E6: OPEN-01 | J6: =IFERROR(H6*(SUMIFS($G$1:G5,$B$1:B5,B6)-SUMIFS($I$1:I5,$B$1:B5,B6))/(SUMIFS($F$1:F5,$B$1:B5,B6)-SUMIFS($H$1:H5,$B$1:B5,B6)),0) -> 0 | K6: =IF(B6="","",SUMIFS($F$2:F6,$B$2:B6,B6)-SUMIFS($H$2:H6,$B$2:B6,B6)) -> 0 | L6: =IF(B6="","",SUMIFS($G$2:G6,$B$2:B6,B6)-SUMIFS($I$2:I6,$B$2:B6,B6)) -> 0 | M6: =IFERROR(L6/K6,0) -> 0
A7: 46266 | B7: RM001 | C7: {=IFERROR(INDEX('Item Master'!$B:$B,MATCH(B7,'Item Master'!$A:$A,0)),"")} -> Raw Material A | D7: Production-Out | E7: PROD-001 | J7: =IFERROR(H7*(SUMIFS($G$1:G6,$B$1:B6,B7)-SUMIFS($I$1:I6,$B$1:B6,B7))/(SUMIFS($F$1:F6,$B$1:B6,B7)-SUMIFS($H$1:H6,$B$1:B6,B7)),0) -> 0 | K7: =IF(B7="","",SUMIFS($F$2:F7,$B$2:B7,B7)-SUMIFS($H$2:H7,$B$2:B7,B7)) -> 0 | L7: =IF(B7="","",SUMIFS($G$2:G7,$B$2:B7,B7)-SUMIFS($I$2:I7,$B$2:B7,B7)) -> 0 | M7: =IFERROR(L7/K7,0) -> 0
A8: 46266 | B8: WIP001 | C8: {=IFERROR(INDEX('Item Master'!$B:$B,MATCH(B8,'Item Master'!$A:$A,0)),"")} -> Semi-Finished Stage 1 | D8: Production-In | E8: PROD-001 | J8: =IFERROR(H8*(SUMIFS($G$1:G7,$B$1:B7,B8)-SUMIFS($I$1:I7,$B$1:B7,B8))/(SUMIFS($F$1:F7,$B$1:B7,B8)-SUMIFS($H$1:H7,$B$1:B7,B8)),0) -> 0 | K8: =IF(B8="","",SUMIFS($F$2:F8,$B$2:B8,B8)-SUMIFS($H$2:H8,$B$2:B8,B8)) -> 0 | L8: =IF(B8="","",SUMIFS($G$2:G8,$B$2:B8,B8)-SUMIFS($I$2:I8,$B$2:B8,B8)) -> 0 | M8: =IFERROR(L8/K8,0) -> 0
A9: 46266 | B9: WIP001 | C9: {=IFERROR(INDEX('Item Master'!$B:$B,MATCH(B9,'Item Master'!$A:$A,0)),"")} -> Semi-Finished Stage 1 | D9: Production-Out | E9: PROD-002 | J9: =IFERROR(H9*(SUMIFS($G$1:G8,$B$1:B8,B9)-SUMIFS($I$1:I8,$B$1:B8,B9))/(SUMIFS($F$1:F8,$B$1:B8,B9)-SUMIFS($H$1:H8,$B$1:B8,B9)),0) -> 0 | K9: =IF(B9="","",SUMIFS($F$2:F9,$B$2:B9,B9)-SUMIFS($H$2:H9,$B$2:B9,B9)) -> 0 | L9: =IF(B9="","",SUMIFS($G$2:G9,$B$2:B9,B9)-SUMIFS($I$2:I9,$B$2:B9,B9)) -> 0 | M9: =IFERROR(L9/K9,0) -> 0
A10: 46266 | B10: RM002 | C10: {=IFERROR(INDEX('Item Master'!$B:$B,MATCH(B10,'Item Master'!$A:$A,0)),"")} -> Raw Material B | D10: Production-Out | E10: PROD-002 | J10: =IFERROR(H10*(SUMIFS($G$1:G9,$B$1:B9,B10)-SUMIFS($I$1:I9,$B$1:B9,B10))/(SUMIFS($F$1:F9,$B$1:B9,B10)-SUMIFS($H$1:H9,$B$1:B9,B10)),0) -> 0 | K10: =IF(B10="","",SUMIFS($F$2:F10,$B$2:B10,B10)-SUMIFS($H$2:H10,$B$2:B10,B10)) -> 0 | L10: =IF(B10="","",SUMIFS($G$2:G10,$B$2:B10,B10)-SUMIFS($I$2:I10,$B$2:B10,B10)) -> 0 | M10: =IFERROR(L10/K10,0) -> 0
A11: 46266 | B11: WIP002 | C11: {=IFERROR(INDEX('Item Master'!$B:$B,MATCH(B11,'Item Master'!$A:$A,0)),"")} -> Semi-Finished Stage 2 | D11: Production-In | E11: PROD-002 | J11: =IFERROR(H11*(SUMIFS($G$1:G10,$B$1:B10,B11)-SUMIFS($I$1:I10,$B$1:B10,B11))/(SUMIFS($F$1:F10,$B$1:B10,B11)-SUMIFS($H$1:H10,$B$1:B10,B11)),0) -> 0 | K11: =IF(B11="","",SUMIFS($F$2:F11,$B$2:B11,B11)-SUMIFS($H$2:H11,$B$2:B11,B11)) -> 0 | L11: =IF(B11="","",SUMIFS($G$2:G11,$B$2:B11,B11)-SUMIFS($I$2:I11,$B$2:B11,B11)) -> 0 | M11: =IFERROR(L11/K11,0) -> 0
A12: 46266 | B12: WIP002 | C12: {=IFERROR(INDEX('Item Master'!$B:$B,MATCH(B12,'Item Master'!$A:$A,0)),"")} -> Semi-Finished Stage 2 | D12: Production-Out | E12: PROD-003 | J12: =IFERROR(H12*(SUMIFS($G$1:G11,$B$1:B11,B12)-SUMIFS($I$1:I11,$B$1:B11,B12))/(SUMIFS($F$1:F11,$B$1:B11,B12)-SUMIFS($H$1:H11,$B$1:B11,B12)),0) -> 0 | K12: =IF(B12="","",SUMIFS($F$2:F12,$B$2:B12,B12)-SUMIFS($H$2:H12,$B$2:B12,B12)) -> 0 | L12: =IF(B12="","",SUMIFS($G$2:G12,$B$2:B12,B12)-SUMIFS($I$2:I12,$B$2:B12,B12)) -> 0 | M12: =IFERROR(L12/K12,0) -> 0
A13: 46266 | B13: PKG001 | C13: {=IFERROR(INDEX('Item Master'!$B:$B,MATCH(B13,'Item Master'!$A:$A,0)),"")} -> Packaging Box | D13: Production-Out | E13: PROD-003 | J13: =IFERROR(H13*(SUMIFS($G$1:G12,$B$1:B12,B13)-SUMIFS($I$1:I12,$B$1:B12,B13))/(SUMIFS($F$1:F12,$B$1:B12,B13)-SUMIFS($H$1:H12,$B$1:B12,B13)),0) -> 0 | K13: =IF(B13="","",SUMIFS($F$2:F13,$B$2:B13,B13)-SUMIFS($H$2:H13,$B$2:B13,B13)) -> 0 | L13: =IF(B13="","",SUMIFS($G$2:G13,$B$2:B13,B13)-SUMIFS($I$2:I13,$B$2:B13,B13)) -> 0 | M13: =IFERROR(L13/K13,0) -> 0
... A15: 46266 | B15: FG001 | C15: {=IFERROR(INDEX('Item Master'!$B:$B,MATCH(B15,'Item Master'!$A:$A,0)),"")} -> Finished Good X | D15: Sale-Out | E15: SALE-001 | J15: =IFERROR(H15*(SUMIFS($G$1:G14,$B$1:B14,B15)-SUMIFS($I$1:I14,$B$1:B14,B15))/(SUMIFS($F$1:F14,$B$1:B14,B15)-SUMIFS($H$1:H14,$B$1:B14,B15)),0) -> 0 | K15: =IF(B15="","",SUMIFS($F$2:F15,$B$2:B15,B15)-SUMIFS($H$2:H15,$B$2:B15,B15)) -> 0 | L15: =IF(B15="","",SUMIFS($G$2:G15,$B$2:B15,B15)-SUMIFS($I$2:I15,$B$2:B15,B15)) -> 0 | M15: =IFERROR(L15/K15,0) -> 0
A16: 46267 | B16: RMA-014 | C16: {=IF(B16="","",IFERROR(INDEX('Item Master'!$B:$B,MATCH(B16,'Item Master'!$A:$A,0)),""))} -> Resin A | D16: Production-In | E16: srthrfgh | F16: 500 | G16: 750000 | J16: =IFERROR(H16*(SUMIFS($G$1:G15,$B$1:B15,B16)-SUMIFS($I$1:I15,$B$1:B15,B16))/(SUMIFS($F$1:F15,$B$1:B15,B16)-SUMIFS($H$1:H15,$B$1:B15,B16)),0) -> 0 | K16: =IF(B16="","",SUMIFS($F$2:F16,$B$2:B16,B16)-SUMIFS($H$2:H16,$B$2:B16,B16)) -> 500 | L16: =IF(B16="","",SUMIFS($G$2:G16,$B$2:B16,B16)-SUMIFS($I$2:I16,$B$2:B16,B16)) -> 750000 | M16: =IFERROR(L16/K16,0) -> 1500
B17: RMC-003 | C17: {=IF(B17="","",IFERROR(INDEX('Item Master'!$B:$B,MATCH(B17,'Item Master'!$A:$A,0)),""))} -> Elephent Cement | D17: Purchase-In | E17: fgfd | F17: 1000 | G17: 32500 | J17: =IFERROR(H17*(SUMIFS($G$1:G16,$B$1:B16,B17)-SUMIFS($I$1:I16,$B$1:B16,B17))/(SUMIFS($F$1:F16,$B$1:B16,B17)-SUMIFS($H$1:H16,$B$1:B16,B17)),0) -> 0 | K17: =IF(B17="","",SUMIFS($F$2:F17,$B$2:B17,B17)-SUMIFS($H$2:H17,$B$2:B17,B17)) -> 1000 | L17: =IF(B17="","",SUMIFS($G$2:G17,$B$2:B17,B17)-SUMIFS($I$2:I17,$B$2:B17,B17)) -> 32500 | M17: =IFERROR(L17/K17,0) -> 32.5
B18: RMC-003 | C18: {=IF(B18="","",IFERROR(INDEX('Item Master'!$B:$B,MATCH(B18,'Item Master'!$A:$A,0)),""))} -> Elephent Cement | D18: Production-Out | H18: 210 | I18: 7000 | J18: =IFERROR(H18*(SUMIFS($G$1:G17,$B$1:B17,B18)-SUMIFS($I$1:I17,$B$1:B17,B18))/(SUMIFS($F$1:F17,$B$1:B17,B18)-SUMIFS($H$1:H17,$B$1:B17,B18)),0) -> 6825 | K18: =IF(B18="","",SUMIFS($F$2:F18,$B$2:B18,B18)-SUMIFS($H$2:H18,$B$2:B18,B18)) -> 790 | L18: =IF(B18="","",SUMIFS($G$2:G18,$B$2:B18,B18)-SUMIFS($I$2:I18,$B$2:B18,B18)) -> 25500 | M18: =IFERROR(L18/K18,0) -> 32.278481
C19: {=IF(B19="","",IFERROR(INDEX('Item Master'!$B:$B,MATCH(B19,'Item Master'!$A:$A,0)),""))} | J19: =IFERROR(H19*(SUMIFS($G$1:G18,$B$1:B18,B19)-SUMIFS($I$1:I18,$B$1:B18,B19))/(SUMIFS($F$1:F18,$B$1:B18,B19)-SUMIFS($H$1:H18,$B$1:B18,B19)),0) -> 0 | K19: =IF(B19="","",SUMIFS($F$2:F19,$B$2:B19,B19)-SUMIFS($H$2:H19,$B$2:B19,B19)) | L19: =IF(B19="","",SUMIFS($G$2:G19,$B$2:B19,B19)-SUMIFS($I$2:I19,$B$2:B19,B19)) | M19: =IFERROR(L19/K19,0) -> 0
C20: {=IF(B20="","",IFERROR(INDEX('Item Master'!$B:$B,MATCH(B20,'Item Master'!$A:$A,0)),""))} | J20: =IFERROR(H20*(SUMIFS($G$1:G19,$B$1:B19,B20)-SUMIFS($I$1:I19,$B$1:B19,B20))/(SUMIFS($F$1:F19,$B$1:B19,B20)-SUMIFS($H$1:H19,$B$1:B19,B20)),0) -> 0 | K20: =IF(B20="","",SUMIFS($F$2:F20,$B$2:B20,B20)-SUMIFS($H$2:H20,$B$2:B20,B20)) | L20: =IF(B20="","",SUMIFS($G$2:G20,$B$2:B20,B20)-SUMIFS($I$2:I20,$B$2:B20,B20)) | M20: =IFERROR(L20/K20,0) -> 0
C21: {=IF(B21="","",IFERROR(INDEX('Item Master'!$B:$B,MATCH(B21,'Item Master'!$A:$A,0)),""))} | J21: =IFERROR(H21*(SUMIFS($G$1:G20,$B$1:B20,B21)-SUMIFS($I$1:I20,$B$1:B20,B21))/(SUMIFS($F$1:F20,$B$1:B20,B21)-SUMIFS($H$1:H20,$B$1:B20,B21)),0) -> 0 | K21: =IF(B21="","",SUMIFS($F$2:F21,$B$2:B21,B21)-SUMIFS($H$2:H21,$B$2:B21,B21)) | L21: =IF(B21="","",SUMIFS($G$2:G21,$B$2:B21,B21)-SUMIFS($I$2:I21,$B$2:B21,B21)) | M21: =IFERROR(L21/K21,0) -> 0
C22: {=IF(B22="","",IFERROR(INDEX('Item Master'!$B:$B,MATCH(B22,'Item Master'!$A:$A,0)),""))} | J22: =IFERROR(H22*(SUMIFS($G$1:G21,$B$1:B21,B22)-SUMIFS($I$1:I21,$B$1:B21,B22))/(SUMIFS($F$1:F21,$B$1:B21,B22)-SUMIFS($H$1:H21,$B$1:B21,B22)),0) -> 0 | K22: =IF(B22="","",SUMIFS($F$2:F22,$B$2:B22,B22)-SUMIFS($H$2:H22,$B$2:B22,B22)) | L22: =IF(B22="","",SUMIFS($G$2:G22,$B$2:B22,B22)-SUMIFS($I$2:I22,$B$2:B22,B22)) | M22: =IFERROR(L22/K22,0) -> 0
C23: {=IF(B23="","",IFERROR(INDEX('Item Master'!$B:$B,MATCH(B23,'Item Master'!$A:$A,0)),""))} | J23: =IFERROR(H23*(SUMIFS($G$1:G22,$B$1:B22,B23)-SUMIFS($I$1:I22,$B$1:B22,B23))/(SUMIFS($F$1:F22,$B$1:B22,B23)-SUMIFS($H$1:H22,$B$1:B22,B23)),0) -> 0 | K23: =IF(B23="","",SUMIFS($F$2:F23,$B$2:B23,B23)-SUMIFS($H$2:H23,$B$2:B23,B23)) | L23: =IF(B23="","",SUMIFS($G$2:G23,$B$2:B23,B23)-SUMIFS($I$2:I23,$B$2:B23,B23)) | M23: =IFERROR(L23/K23,0) -> 0
C24: {=IF(B24="","",IFERROR(INDEX('Item Master'!$B:$B,MATCH(B24,'Item Master'!$A:$A,0)),""))} | J24: =IFERROR(H24*(SUMIFS($G$1:G23,$B$1:B23,B24)-SUMIFS($I$1:I23,$B$1:B23,B24))/(SUMIFS($F$1:F23,$B$1:B23,B24)-SUMIFS($H$1:H23,$B$1:B23,B24)),0) -> 0 | K24: =IF(B24="","",SUMIFS($F$2:F24,$B$2:B24,B24)-SUMIFS($H$2:H24,$B$2:B24,B24)) | L24: =IF(B24="","",SUMIFS($G$2:G24,$B$2:B24,B24)-SUMIFS($I$2:I24,$B$2:B24,B24)) | M24: =IFERROR(L24/K24,0) -> 0
C25: {=IF(B25="","",IFERROR(INDEX('Item Master'!$B:$B,MATCH(B25,'Item Master'!$A:$A,0)),""))} | J25: =IFERROR(H25*(SUMIFS($G$1:G24,$B$1:B24,B25)-SUMIFS($I$1:I24,$B$1:B24,B25))/(SUMIFS($F$1:F24,$B$1:B24,B25)-SUMIFS($H$1:H24,$B$1:B24,B25)),0) -> 0 | K25: =IF(B25="","",SUMIFS($F$2:F25,$B$2:B25,B25)-SUMIFS($H$2:H25,$B$2:B25,B25)) | L25: =IF(B25="","",SUMIFS($G$2:G25,$B$2:B25,B25)-SUMIFS($I$2:I25,$B$2:B25,B25)) | M25: =IFERROR(L25/K25,0) -> 0
C26: {=IF(B26="","",IFERROR(INDEX('Item Master'!$B:$B,MATCH(B26,'Item Master'!$A:$A,0)),""))} | J26: =IFERROR(H26*(SUMIFS($G$1:G25,$B$1:B25,B26)-SUMIFS($I$1:I25,$B$1:B25,B26))/(SUMIFS($F$1:F25,$B$1:B25,B26)-SUMIFS($H$1:H25,$B$1:B25,B26)),0) -> 0 | K26: =IF(B26="","",SUMIFS($F$2:F26,$B$2:B26,B26)-SUMIFS($H$2:H26,$B$2:B26,B26)) | L26: =IF(B26="","",SUMIFS($G$2:G26,$B$2:B26,B26)-SUMIFS($I$2:I26,$B$2:B26,B26)) | M26: =IFERROR(L26/K26,0) -> 0
C27: {=IF(B27="","",IFERROR(INDEX('Item Master'!$B:$B,MATCH(B27,'Item Master'!$A:$A,0)),""))} | J27: =IFERROR(H27*(SUMIFS($G$1:G26,$B$1:B26,B27)-SUMIFS($I$1:I26,$B$1:B26,B27))/(SUMIFS($F$1:F26,$B$1:B26,B27)-SUMIFS($H$1:H26,$B$1:B26,B27)),0) -> 0 | K27: =IF(B27="","",SUMIFS($F$2:F27,$B$2:B27,B27)-SUMIFS($H$2:H27,$B$2:B27,B27)) | L27: =IF(B27="","",SUMIFS($G$2:G27,$B$2:B27,B27)-SUMIFS($I$2:I27,$B$2:B27,B27)) | M27: =IFERROR(L27/K27,0) -> 0
C28: {=IF(B28="","",IFERROR(INDEX('Item Master'!$B:$B,MATCH(B28,'Item Master'!$A:$A,0)),""))} | J28: =IFERROR(H28*(SUMIFS($G$1:G27,$B$1:B27,B28)-SUMIFS($I$1:I27,$B$1:B27,B28))/(SUMIFS($F$1:F27,$B$1:B27,B28)-SUMIFS($H$1:H27,$B$1:B27,B28)),0) -> 0 | K28: =IF(B28="","",SUMIFS($F$2:F28,$B$2:B28,B28)-SUMIFS($H$2:H28,$B$2:B28,B28)) | L28: =IF(B28="","",SUMIFS($G$2:G28,$B$2:B28,B28)-SUMIFS($I$2:I28,$B$2:B28,B28)) | M28: =IFERROR(L28/K28,0) -> 0
C29: {=IF(B29="","",IFERROR(INDEX('Item Master'!$B:$B,MATCH(B29,'Item Master'!$A:$A,0)),""))} | J29: =IFERROR(H29*(SUMIFS($G$1:G28,$B$1:B28,B29)-SUMIFS($I$1:I28,$B$1:B28,B29))/(SUMIFS($F$1:F28,$B$1:B28,B29)-SUMIFS($H$1:H28,$B$1:B28,B29)),0) -> 0 | K29: =IF(B29="","",SUMIFS($F$2:F29,$B$2:B29,B29)-SUMIFS($H$2:H29,$B$2:B29,B29)) | L29: =IF(B29="","",SUMIFS($G$2:G29,$B$2:B29,B29)-SUMIFS($I$2:I29,$B$2:B29,B29)) | M29: =IFERROR(L29/K29,0) -> 0
C30: {=IF(B30="","",IFERROR(INDEX('Item Master'!$B:$B,MATCH(B30,'Item Master'!$A:$A,0)),""))} | J30: =IFERROR(H30*(SUMIFS($G$1:G29,$B$1:B29,B30)-SUMIFS($I$1:I29,$B$1:B29,B30))/(SUMIFS($F$1:F29,$B$1:B29,B30)-SUMIFS($H$1:H29,$B$1:B29,B30)),0) -> 0 | K30: =IF(B30="","",SUMIFS($F$2:F30,$B$2:B30,B30)-SUMIFS($H$2:H30,$B$2:B30,B30)) | L30: =IF(B30="","",SUMIFS($G$2:G30,$B$2:B30,B30)-SUMIFS($I$2:I30,$B$2:B30,B30)) | M30: =IFERROR(L30/K30,0) -> 0
... C200: {=IF(B200="","",IFERROR(INDEX('Item Master'!$B:$B,MATCH(B200,'Item Master'!$A:$A,0)),""))} | J200: =IFERROR(H200*(SUMIFS($G$1:G199,$B$1:B199,B200)-SUMIFS($I$1:I199,$B$1:B199,B200))/(SUMIFS($F$1:F199,$B$1:B199,B200)-SUMIFS($H$1:H199,$B$1:B199,B200)),0) -> 0 | K200: =IF(B200="","",SUMIFS($F$2:F200,$B$2:B200,B200)-SUMIFS($H$2:H200,$B$2:B200,B200)) | L200: =IF(B200="","",SUMIFS($G$2:G200,$B$2:B200,B200)-SUMIFS($I$2:I200,$B$2:B200,B200)) | M200: =IFERROR(L200/K200,0) -> 0

Sheet General Ledger
A1: হিসাব কোড (Account Code) | B1: হিসাবের নাম (Account Name) | C1: ধরন (Type) | D1: সেগমেন্ট (Segment) | E1: প্রারম্ভিক ডেবিট (Opening Debit) | F1: প্রারম্ভিক ক্রেডিট (Opening Credit) | G1: মেয়াদকালীন ডেবিট (Period Debit) | H1: মেয়াদকালীন ক্রেডিট (Period Credit) | I1: সমাপনী ডেবিট (Closing Debit) | J1: সমাপনী ক্রেডিট (Closing Credit)
A2: ='Chart of Accounts'!A2 -> 1000 | B2: ='Chart of Accounts'!B2 -> Cash in Hand | C2: ='Chart of Accounts'!C2 -> Asset | D2: ='Chart of Accounts'!D2 -> Shared | E2: =SUMIF('Opening Balances'!$A:$A,A2,'Opening Balances'!$C:$C) -> 0 | F2: =SUMIF('Opening Balances'!$A:$A,A2,'Opening Balances'!$D:$D) -> 0 | G2: =SUMIF('Journal Entries'!$D:$D,A2,'Journal Entries'!$G:$G) -> 0 | H2: =SUMIF('Journal Entries'!$D:$D,A2,'Journal Entries'!$H:$H) -> 0 | I2: =IF((E2-F2+G2-H2)>=0,(E2-F2+G2-H2),0) -> 0 | J2: =IF((E2-F2+G2-H2)<0,-(E2-F2+G2-H2),0) -> 0
A3: ='Chart of Accounts'!A3 -> 1005 | B3: ='Chart of Accounts'!B3 -> Petty Cash | C3: ='Chart of Accounts'!C3 -> Asset | D3: ='Chart of Accounts'!D3 -> Shared | E3: =SUMIF('Opening Balances'!$A:$A,A3,'Opening Balances'!$C:$C) -> 0 | F3: =SUMIF('Opening Balances'!$A:$A,A3,'Opening Balances'!$D:$D) -> 0 | G3: =SUMIF('Journal Entries'!$D:$D,A3,'Journal Entries'!$G:$G) -> 0 | H3: =SUMIF('Journal Entries'!$D:$D,A3,'Journal Entries'!$H:$H) -> 0 | I3: =IF((E3-F3+G3-H3)>=0,(E3-F3+G3-H3),0) -> 0 | J3: =IF((E3-F3+G3-H3)<0,-(E3-F3+G3-H3),0) -> 0
A4: ='Chart of Accounts'!A4 -> 1010 | B4: ='Chart of Accounts'!B4 -> Bank Account - Main | C4: ='Chart of Accounts'!C4 -> Asset | D4: ='Chart of Accounts'!D4 -> Shared | E4: =SUMIF('Opening Balances'!$A:$A,A4,'Opening Balances'!$C:$C) -> 500000 | F4: =SUMIF('Opening Balances'!$A:$A,A4,'Opening Balances'!$D:$D) -> 0 | G4: =SUMIF('Journal Entries'!$D:$D,A4,'Journal Entries'!$G:$G) -> 0 | H4: =SUMIF('Journal Entries'!$D:$D,A4,'Journal Entries'!$H:$H) -> 3800 | I4: =IF((E4-F4+G4-H4)>=0,(E4-F4+G4-H4),0) -> 496200 | J4: =IF((E4-F4+G4-H4)<0,-(E4-F4+G4-H4),0) -> 0
A5: ='Chart of Accounts'!A5 -> 1011 | B5: ='Chart of Accounts'!B5 -> Bank Account - Secondary | C5: ='Chart of Accounts'!C5 -> Asset | D5: ='Chart of Accounts'!D5 -> Shared | E5: =SUMIF('Opening Balances'!$A:$A,A5,'Opening Balances'!$C:$C) -> 0 | F5: =SUMIF('Opening Balances'!$A:$A,A5,'Opening Balances'!$D:$D) -> 0 | G5: =SUMIF('Journal Entries'!$D:$D,A5,'Journal Entries'!$G:$G) -> 0 | H5: =SUMIF('Journal Entries'!$D:$D,A5,'Journal Entries'!$H:$H) -> 0 | I5: =IF((E5-F5+G5-H5)>=0,(E5-F5+G5-H5),0) -> 0 | J5: =IF((E5-F5+G5-H5)<0,-(E5-F5+G5-H5),0) -> 0
A6: ='Chart of Accounts'!A6 -> 1020 | B6: ='Chart of Accounts'!B6 -> L/C Margin Deposit | C6: ='Chart of Accounts'!C6 -> Asset | D6: ='Chart of Accounts'!D6 -> Import | E6: =SUMIF('Opening Balances'!$A:$A,A6,'Opening Balances'!$C:$C) -> 0 | F6: =SUMIF('Opening Balances'!$A:$A,A6,'Opening Balances'!$D:$D) -> 0 | G6: =SUMIF('Journal Entries'!$D:$D,A6,'Journal Entries'!$G:$G) -> 0 | H6: =SUMIF('Journal Entries'!$D:$D,A6,'Journal Entries'!$H:$H) -> 0 | I6: =IF((E6-F6+G6-H6)>=0,(E6-F6+G6-H6),0) -> 0 | J6: =IF((E6-F6+G6-H6)<0,-(E6-F6+G6-H6),0) -> 0
A7: ='Chart of Accounts'!A7 -> 1100 | B7: ='Chart of Accounts'!B7 -> Accounts Receivable - Local | C7: ='Chart of Accounts'!C7 -> Asset | D7: ='Chart of Accounts'!D7 -> Shared | E7: =SUMIF('Opening Balances'!$A:$A,A7,'Opening Balances'!$C:$C) -> 0 | F7: =SUMIF('Opening Balances'!$A:$A,A7,'Opening Balances'!$D:$D) -> 0 | G7: =SUMIF('Journal Entries'!$D:$D,A7,'Journal Entries'!$G:$G) -> 4000 | H7: =SUMIF('Journal Entries'!$D:$D,A7,'Journal Entries'!$H:$H) -> 0 | I7: =IF((E7-F7+G7-H7)>=0,(E7-F7+G7-H7),0) -> 4000 | J7: =IF((E7-F7+G7-H7)<0,-(E7-F7+G7-H7),0) -> 0
A8: ='Chart of Accounts'!A8 -> 1101 | B8: ='Chart of Accounts'!B8 -> Accounts Receivable - Export | C8: ='Chart of Accounts'!C8 -> Asset | D8: ='Chart of Accounts'!D8 -> Shared | E8: =SUMIF('Opening Balances'!$A:$A,A8,'Opening Balances'!$C:$C) -> 0 | F8: =SUMIF('Opening Balances'!$A:$A,A8,'Opening Balances'!$D:$D) -> 0 | G8: =SUMIF('Journal Entries'!$D:$D,A8,'Journal Entries'!$G:$G) -> 0 | H8: =SUMIF('Journal Entries'!$D:$D,A8,'Journal Entries'!$H:$H) -> 0 | I8: =IF((E8-F8+G8-H8)>=0,(E8-F8+G8-H8),0) -> 0 | J8: =IF((E8-F8+G8-H8)<0,-(E8-F8+G8-H8),0) -> 0
A9: ='Chart of Accounts'!A9 -> 1110 | B9: ='Chart of Accounts'!B9 -> Advance to Suppliers | C9: ='Chart of Accounts'!C9 -> Asset | D9: ='Chart of Accounts'!D9 -> Shared | E9: =SUMIF('Opening Balances'!$A:$A,A9,'Opening Balances'!$C:$C) -> 0 | F9: =SUMIF('Opening Balances'!$A:$A,A9,'Opening Balances'!$D:$D) -> 0 | G9: =SUMIF('Journal Entries'!$D:$D,A9,'Journal Entries'!$G:$G) -> 0 | H9: =SUMIF('Journal Entries'!$D:$D,A9,'Journal Entries'!$H:$H) -> 0 | I9: =IF((E9-F9+G9-H9)>=0,(E9-F9+G9-H9),0) -> 0 | J9: =IF((E9-F9+G9-H9)<0,-(E9-F9+G9-H9),0) -> 0
A10: ='Chart of Accounts'!A10 -> 1120 | B10: ='Chart of Accounts'!B10 -> Advance Income Tax (AIT) | C10: ='Chart of Accounts'!C10 -> Asset | D10: ='Chart of Accounts'!D10 -> Shared | E10: =SUMIF('Opening Balances'!$A:$A,A10,'Opening Balances'!$C:$C) -> 0 | F10: =SUMIF('Opening Balances'!$A:$A,A10,'Opening Balances'!$D:$D) -> 0 | G10: =SUMIF('Journal Entries'!$D:$D,A10,'Journal Entries'!$G:$G) -> 0 | H10: =SUMIF('Journal Entries'!$D:$D,A10,'Journal Entries'!$H:$H) -> 0 | I10: =IF((E10-F10+G10-H10)>=0,(E10-F10+G10-H10),0) -> 0 | J10: =IF((E10-F10+G10-H10)<0,-(E10-F10+G10-H10),0) -> 0
A11: ='Chart of Accounts'!A11 -> 1130 | B11: ='Chart of Accounts'!B11 -> VAT Current Account (Input VAT) | C11: ='Chart of Accounts'!C11 -> Asset | D11: ='Chart of Accounts'!D11 -> Shared | E11: =SUMIF('Opening Balances'!$A:$A,A11,'Opening Balances'!$C:$C) -> 0 | F11: =SUMIF('Opening Balances'!$A:$A,A11,'Opening Balances'!$D:$D) -> 0 | G11: =SUMIF('Journal Entries'!$D:$D,A11,'Journal Entries'!$G:$G) -> 0 | H11: =SUMIF('Journal Entries'!$D:$D,A11,'Journal Entries'!$H:$H) -> 0 | I11: =IF((E11-F11+G11-H11)>=0,(E11-F11+G11-H11),0) -> 0 | J11: =IF((E11-F11+G11-H11)<0,-(E11-F11+G11-H11),0) -> 0
A12: ='Chart of Accounts'!A12 -> 1140 | B12: ='Chart of Accounts'!B12 -> Advance to Employees | C12: ='Chart of Accounts'!C12 -> Asset | D12: ='Chart of Accounts'!D12 -> Shared | E12: =SUMIF('Opening Balances'!$A:$A,A12,'Opening Balances'!$C:$C) -> 0 | F12: =SUMIF('Opening Balances'!$A:$A,A12,'Opening Balances'!$D:$D) -> 0 | G12: =SUMIF('Journal Entries'!$D:$D,A12,'Journal Entries'!$G:$G) -> 0 | H12: =SUMIF('Journal Entries'!$D:$D,A12,'Journal Entries'!$H:$H) -> 0 | I12: =IF((E12-F12+G12-H12)>=0,(E12-F12+G12-H12),0) -> 0 | J12: =IF((E12-F12+G12-H12)<0,-(E12-F12+G12-H12),0) -> 0
A13: ='Chart of Accounts'!A13 -> 1150 | B13: ='Chart of Accounts'!B13 -> Prepaid Expenses | C13: ='Chart of Accounts'!C13 -> Asset | D13: ='Chart of Accounts'!D13 -> Shared | E13: =SUMIF('Opening Balances'!$A:$A,A13,'Opening Balances'!$C:$C) -> 0 | F13: =SUMIF('Opening Balances'!$A:$A,A13,'Opening Balances'!$D:$D) -> 0 | G13: =SUMIF('Journal Entries'!$D:$D,A13,'Journal Entries'!$G:$G) -> 0 | H13: =SUMIF('Journal Entries'!$D:$D,A13,'Journal Entries'!$H:$H) -> 0 | I13: =IF((E13-F13+G13-H13)>=0,(E13-F13+G13-H13),0) -> 0 | J13: =IF((E13-F13+G13-H13)<0,-(E13-F13+G13-H13),0) -> 0
... A90: ='Chart of Accounts'!A90 -> 7020 | B90: ='Chart of Accounts'!B90 -> Miscellaneous Income | C90: ='Chart of Accounts'!C90 -> Other Income | D90: ='Chart of Accounts'!D90 -> Shared | E90: =SUMIF('Opening Balances'!$A:$A,A90,'Opening Balances'!$C:$C) -> 0 | F90: =SUMIF('Opening Balances'!$A:$A,A90,'Opening Balances'!$D:$D) -> 0 | G90: =SUMIF('Journal Entries'!$D:$D,A90,'Journal Entries'!$G:$G) -> 0 | H90: =SUMIF('Journal Entries'!$D:$D,A90,'Journal Entries'!$H:$H) -> 0 | I90: =IF((E90-F90+G90-H90)>=0,(E90-F90+G90-H90),0) -> 0 | J90: =IF((E90-F90+G90-H90)<0,-(E90-F90+G90-H90),0) -> 0
B92: মোট (TOTAL) | I92: =SUM(I2:I90) -> 804000 | J92: =SUM(J2:J90) -> 804000

Sheet Trial Balance
A1: তারিখ পর্যন্ত (As of): | B1: =TODAY() -> 46279
A3: হিসাব কোড (Account Code) | B3: হিসাবের নাম (Account Name) | C3: ধরন (Type) | D3: ডেবিট (Debit) | E3: ক্রেডিট (Credit)
A4: ='General Ledger'!A2 -> 1000 | B4: ='General Ledger'!B2 -> Cash in Hand | C4: ='General Ledger'!C2 -> Asset | D4: ='General Ledger'!I2 -> 0 | E4: ='General Ledger'!J2 -> 0
A5: ='General Ledger'!A3 -> 1005 | B5: ='General Ledger'!B3 -> Petty Cash | C5: ='General Ledger'!C3 -> Asset | D5: ='General Ledger'!I3 -> 0 | E5: ='General Ledger'!J3 -> 0
A6: ='General Ledger'!A4 -> 1010 | B6: ='General Ledger'!B4 -> Bank Account - Main | C6: ='General Ledger'!C4 -> Asset | D6: ='General Ledger'!I4 -> 496200 | E6: ='General Ledger'!J4 -> 0
A7: ='General Ledger'!A5 -> 1011 | B7: ='General Ledger'!B5 -> Bank Account - Secondary | C7: ='General Ledger'!C5 -> Asset | D7: ='General Ledger'!I5 -> 0 | E7: ='General Ledger'!J5 -> 0
A8: ='General Ledger'!A6 -> 1020 | B8: ='General Ledger'!B6 -> L/C Margin Deposit | C8: ='General Ledger'!C6 -> Asset | D8: ='General Ledger'!I6 -> 0 | E8: ='General Ledger'!J6 -> 0
A9: ='General Ledger'!A7 -> 1100 | B9: ='General Ledger'!B7 -> Accounts Receivable - Local | C9: ='General Ledger'!C7 -> Asset | D9: ='General Ledger'!I7 -> 4000 | E9: ='General Ledger'!J7 -> 0
A10: ='General Ledger'!A8 -> 1101 | B10: ='General Ledger'!B8 -> Accounts Receivable - Export | C10: ='General Ledger'!C8 -> Asset | D10: ='General Ledger'!I8 -> 0 | E10: ='General Ledger'!J8 -> 0
A11: ='General Ledger'!A9 -> 1110 | B11: ='General Ledger'!B9 -> Advance to Suppliers | C11: ='General Ledger'!C9 -> Asset | D11: ='General Ledger'!I9 -> 0 | E11: ='General Ledger'!J9 -> 0
A12: ='General Ledger'!A10 -> 1120 | B12: ='General Ledger'!B10 -> Advance Income Tax (AIT) | C12: ='General Ledger'!C10 -> Asset | D12: ='General Ledger'!I10 -> 0 | E12: ='General Ledger'!J10 -> 0
A13: ='General Ledger'!A11 -> 1130 | B13: ='General Ledger'!B11 -> VAT Current Account (Input VAT) | C13: ='General Ledger'!C11 -> Asset | D13: ='General Ledger'!I11 -> 0 | E13: ='General Ledger'!J11 -> 0
A14: ='General Ledger'!A12 -> 1140 | B14: ='General Ledger'!B12 -> Advance to Employees | C14: ='General Ledger'!C12 -> Asset | D14: ='General Ledger'!I12 -> 0 | E14: ='General Ledger'!J12 -> 0
A15: ='General Ledger'!A13 -> 1150 | B15: ='General Ledger'!B13 -> Prepaid Expenses | C15: ='General Ledger'!C13 -> Asset | D15: ='General Ledger'!I13 -> 0 | E15: ='General Ledger'!J13 -> 0
... A92: ='General Ledger'!A90 -> 7020 | B92: ='General Ledger'!B90 -> Miscellaneous Income | C92: ='General Ledger'!C90 -> Other Income | D92: ='General Ledger'!I90 -> 0 | E92: ='General Ledger'!J90 -> 0
B94: মোট (TOTAL) | D94: =SUM(D4:D92) -> 804000 | E94: =SUM(E4:E92) -> 804000
B95: পার্থক্য (Difference) — অবশ্যই ০ হতে হবে | D95: =D94-E94 -> 0

Sheet P&L by Segment
A1: সেগমেন্ট (Segment) | B1: রাজস্ব/বিক্রয় (Revenue) | C1: বিক্রীত পণ্যের খরচ (COGS) | D1: মোট মুনাফা (Gross Profit) | E1: মোট মুনাফার হার % (Gross Margin %)
A2: Import | B2: =SUMIFS('General Ledger'!$J$2:$J$90,'General Ledger'!$D$2:$D$90,A2,'General Ledger'!$C$2:$C$90,"Revenue")-SUMIFS('General Ledger'!$I$2:$I$90,'General Ledger'!$D$2:$D$90,A2,'General Ledger'!$C$2:$C$90,"Revenue") -> 0 | C2: =SUMIFS('General Ledger'!$I$2:$I$90,'General Ledger'!$D$2:$D$90,A2,'General Ledger'!$C$2:$C$90,"COGS") -> 0 | D2: =B2-C2 -> 0 | E2: =IFERROR(D2/B2,0) -> 0
